<?xml version="1.0" ?>
<robot name="cablebot" xmlns:xacro="http://www.ros.org/wiki/xacro">

  <xacro:include filename="$(find uasl_crane_description)/urdf/cablebot.gazebo" />

  <material name="black">
    <color rgba="0.0 0.0 0.0 1.0"/>
  </material>
  <material name="orange">
    <color rgba="1.0 0.4 0.0 1.0"/>
  </material>

  <link name="world"/>

  <joint name="fixed" type="fixed">
    <parent link="world"/>
    <child link="link1"/>
  </joint>

  <link name="link1">
    <collision>
      <origin xyz="0 0 0.5" rpy="0 0 0"/>
      <geometry>
        <box size="5 2.5 1"/>
      </geometry>
    </collision>
    <visual>
      <origin xyz="0 0 0.5" rpy="0 0 0"/>
      <geometry>
        <box size="5 2.5 1"/>
      </geometry>
      <material name="orange"/>
    </visual>
    <inertial>
      <origin xyz="0 0 0.5" rpy="0 0 0"/>
      <mass value="10000"/>
      <inertia ixx="1.0" ixy="0.0" ixz="1.0" iyy="0.0" iyz="1.0" izz="0.0"/>
    </inertial>
  </link>

  <joint name="joint1" type="revolute">
    <parent link="link1"/>
    <child link="link2"/>
    <origin xyz="0 0 1" rpy="0 0 0"/>
    <axis xyz="0 0 -1"/>
    <limit effort="100000000" lower="-3.14" upper="3.14" velocity="0.15"/>
  </joint>

  <link name="link2">
    <visual>
      <origin xyz="0 0 0.1" rpy="0 0 0"/>
      <geometry>
        <cylinder radius="0.8" length="0.2"/>
      </geometry>
      <material name="black"/>
    </visual>
    <inertial>
      <origin xyz="0 0 0.25" rpy="0 0 0"/>
      <mass value="1"/>
      <inertia ixx="1.0" ixy="0.0" ixz="0.0" iyy="1.0" iyz="0.0" izz="1.0"/>
    </inertial>
  </link>

  <joint name="joint2" type="revolute">
    <parent link="link2"/>
    <child link="link3"/>
    <origin xyz="0 0 0.3" rpy="0 0 0"/>
    <axis xyz="0 -1 0"/>
    <limit effort="100000000" lower="0" upper="1.5" velocity="0.15"/>
  </joint>

  <link name="link3">
    <visual>
      <origin xyz="2 0 0" rpy="0 0 0"/>
      <geometry>
        <box size="5 0.25 0.5"/>
      </geometry>
      <material name="orange"/>
    </visual>
    <inertial>
      <origin xyz="0 0 0" rpy="0 0 0"/>
      <mass value="1"/>
      <inertia ixx="1.0" ixy="0.0" ixz="0.0" iyy="1.0" iyz="0.0" izz="1.0"/>
    </inertial>
  </link>

  <joint name="joint3" type="prismatic">
    <parent link="link3"/>
    <child link="link4"/>
    <origin xyz="0 0 0" rpy="0 0 0"/>
    <axis xyz="1 0 0"/>
    <limit effort="30" lower="0" upper="3.5" velocity="1.0"/>
  </joint>

  <link name="link4">
    <visual>
      <origin xyz="2.6 0 0" rpy="0 0 0"/>
      <geometry>
        <box size="4 0.2 0.4"/>
      </geometry>
      <material name="orange"/>
    </visual>
    <inertial>
      <origin xyz="0 0 0" rpy="0 0 0"/>
      <mass value="0.001"/>
      <inertia ixx="1.0" ixy="0.0" ixz="0.0" iyy="1.0" iyz="0.0" izz="1.0"/>
    </inertial>
  </link>

  <joint name="joint4" type="continuous">
    <parent link="link4"/>
    <child link="link5"/>
    <origin xyz="0 0 0" rpy="0 0 0"/>
    <axis xyz="1 0 0"/>
    <limit effort="30" velocity="3.14"/>
  </joint>

  <link name="link5">
    <visual>
      <origin xyz="4.65 0 0" rpy="0 0 0"/>
      <geometry>
        <box size="0.2 0.1 0.05"/>
      </geometry>
      <material name="black"/>
    </visual>
    <inertial>
      <origin xyz="0 0 0" rpy="0 0 0"/>
      <mass value="0"/>
      <inertia ixx="1.0" ixy="0.0" ixz="0.0" iyy="1.0" iyz="0.0" izz="1.0"/>
    </inertial>
  </link>

  <xacro:include filename="$(find velodyne_description)/urdf/VLP-16.urdf.xacro"/>
  <VLP-16 parent="link5" name="velodyne" topic="velodyne_points" hz="10" samples="440">
    <origin xyz="4.7 0 0.025" rpy="0 0 0" />
  </VLP-16>

  <joint name="joint5" type="continuous">
    <parent link="link4"/>
    <child link="link6"/>
    <origin xyz="5 0 0" rpy="0 0 0"/>
    <axis xyz="0 1 0"/>
  </joint>

  <link name="link6">
    <!--<visual>
      <origin xyz="0 0 0" rpy="0 0 0"/>
      <geometry>
        <box size="0.01 0.01 0.01"/>
      </geometry>
      <material name="black"/>
    </visual>-->
    <inertial>
      <origin xyz="0 0 0" rpy="0 0 0"/>
      <mass value="0.00001"/>
      <inertia ixx="1.0" ixy="0.0" ixz="0.0" iyy="1.0" iyz="0.0" izz="1.0"/>
    </inertial>
  </link>

  <joint name="joint6" type="prismatic">
    <parent link="link6"/>
    <child link="link7"/>
    <origin xyz="0 0 0" rpy="0 0 0"/>
    <axis xyz="0 0 1"/>
    <limit effort="0.05" lower="-7" upper="-0.8" velocity="0.2"/>
  </joint>

  <link name="link7">
    <visual>
      <origin xyz="0 0 4" rpy="0 0 0"/>
      <geometry>
        <box size="0.01 0.01 8"/>
      </geometry>
      <material name="black"/>
    </visual>
    <inertial>
      <origin xyz="0 0 0" rpy="0 0 0"/>
      <mass value="0.00001"/>
      <inertia ixx="1.0" ixy="0.0" ixz="0.0" iyy="1.0" iyz="0.0" izz="1.0"/>
    </inertial>
  </link>

  <joint name="joint7" type="fixed">
    <parent link="link7"/>
    <child link="link8"/>
  </joint>

  <link name="link8">
    <collision>
      <origin xyz="0 0 0" rpy="0 0 0"/>
      <geometry>
        <box size="1.0 1.0 1.0"/>
      </geometry>
    </collision>
    <visual>
      <origin xyz="0 0 0" rpy="0 0 0"/>
      <geometry>
        <box size="1.0 1.0 1.0"/>
      </geometry>
      <material name="orange"/>
    </visual>
    <inertial>
      <origin xyz="0 0 0" rpy="0 0 0"/>
      <mass value="0.0"/>
      <inertia ixx="1.0" ixy="0.0" ixz="0.0" iyy="1.0" iyz="0.0" izz="1.0"/>
    </inertial>
  </link>

  <transmission name="tran1">
    <type>transmission_interface/SimpleTransmission</type>
    <joint name="joint1">
      <hardwareInterface>hardware_interface/EffortJointInterface</hardwareInterface>
    </joint>
    <actuator name="motor1">
      <hardwareInterface>hardware_interface/EffortJointInterface</hardwareInterface>
      <mechanicalReduction>1</mechanicalReduction>
    </actuator>
  </transmission>

  <transmission name="tran2">
    <type>transmission_interface/SimpleTransmission</type>
    <joint name="joint2">
      <hardwareInterface>hardware_interface/EffortJointInterface</hardwareInterface>
    </joint>
    <actuator name="motor2">
      <hardwareInterface>hardware_interface/EffortJointInterface</hardwareInterface>
      <mechanicalReduction>1</mechanicalReduction>
    </actuator>
  </transmission>

  <transmission name="tran3">
    <type>transmission_interface/SimpleTransmission</type>
    <joint name="joint3">
      <hardwareInterface>hardware_interface/EffortJointInterface</hardwareInterface>
    </joint>
    <actuator name="motor3">
      <hardwareInterface>hardware_interface/EffortJointInterface</hardwareInterface>
      <mechanicalReduction>1</mechanicalReduction>
    </actuator>
  </transmission>

  <transmission name="tran4">
    <type>transmission_interface/SimpleTransmission</type>
    <joint name="joint4">
      <hardwareInterface>hardware_interface/EffortJointInterface</hardwareInterface>
    </joint>
    <actuator name="motor4">
      <hardwareInterface>hardware_interface/EffortJointInterface</hardwareInterface>
      <mechanicalReduction>1</mechanicalReduction>
    </actuator>
  </transmission>

  <transmission name="tran5">
    <type>transmission_interface/SimpleTransmission</type>
    <joint name="joint5">
      <hardwareInterface>hardware_interface/EffortJointInterface</hardwareInterface>
    </joint>
    <actuator name="motor5">
      <hardwareInterface>hardware_interface/EffortJointInterface</hardwareInterface>
      <mechanicalReduction>1</mechanicalReduction>
    </actuator>
  </transmission>

  <transmission name="tran6">
    <type>transmission_interface/SimpleTransmission</type>
    <joint name="joint6">
      <hardwareInterface>hardware_interface/EffortJointInterface</hardwareInterface>
    </joint>
    <actuator name="motor6">
      <hardwareInterface>hardware_interface/EffortJointInterface</hardwareInterface>
      <mechanicalReduction>1</mechanicalReduction>
    </actuator>
  </transmission>

</robot>
